Workbook

Sheet Complaint Summary
A1: Complaint Metrics
A4: Open Complaints | B4: =COUNTIF('Complaints Register'!L:L,"Open") -> 5
A5: In Progress | B5: =COUNTIF('Complaints Register'!L:L,"In Progress") -> 0
A6: Waiting for Customer | B6: =COUNTIF('Complaints Register'!L:L,"Waiting for Customer") -> 1
A7: Resolved | B7: =COUNTIF('Complaints Register'!L:L,"Resolved") -> 0
A8: Closed | B8: =COUNTIF('Complaints Register'!L:L,"Closed") -> 17
A9: Total Complaints | B9: =SUM(B4:B8) -> 23

Sheet Complaints Register
A1: Complaint ID | B1: Date Reported | C1: Customer Name | D1: Customer ID / Account | E1: Phone Number | F1: JBL Reported By | G1: Branch / Region | H1: Complaint Category | I1: Complaint Description | J1: LOAN STATUS | K1: LOAN AT RISK | L1: Status | M1: Resolution Details | N1: Date Resolved | O1: Days Open | P1: RISK LEVEL
A2: =IF(B2="","","CMP"&TEXT(ROW()-1,"000")) -> CMP001 | B2: 46325 | C2: GITONGA, JULIUS MAINA | E2: 254713710943 | F2: JACKSON NJOROGE | G2: NYERI | H2: System Damage(Tear/Burst) | I2: bag worn out | J2: Cleared | K2: 0 | L2: Closed | M2: Repair was done | O2: =IF(L2="Closed","",IF(B2="","",TODAY()-B2)) | P2: {=IF(L2<>"Open","",IFS(TODAY()-B2<=30,"Low",TODAY()-B2<=60,"Moderate",TODAY()-B2>60,"High"))}
A3: =IF(B3="","","CMP"&TEXT(ROW()-1,"000")) -> CMP002 | B3: 46038 | C3: KARIUKI, SAMUEL KAMAU | D3: 21414399 | E3: 254711552039 | F3: JACKSON NJOROGE | G3: MURANGA | H3: System Underperformance | I3: system under performing | J3: Non Performing | K3: 28098 | L3: Open | O3: =IF(L3="Closed","",IF(B3="","",TODAY()-B3)) -> 89 | P3: {=IF(L3<>"Open","",IFS(TODAY()-B3<=30,"Low",TODAY()-B3<=60,"Moderate",TODAY()-B3>60,"High"))} -> High
A4: =IF(B4="","","CMP"&TEXT(ROW()-1,"000")) -> CMP003 | B4: 45944 | C4: KABUBI, MARGARET WANJIKU | D4: 24465776 | E4: 254710739000 | F4: JACKSON NJOROGE | G4: NYANDARUA | H4: System Underperformance | I4: system under performing | J4: Non Performing | K4: 55443 | L4: Open | O4: =IF(L4="Closed","",IF(B4="","",TODAY()-B4)) -> 183 | P4: {=IF(L4<>"Open","",IFS(TODAY()-B4<=30,"Low",TODAY()-B4<=60,"Moderate",TODAY()-B4>60,"High"))} -> High
A5: =IF(B5="","","CMP"&TEXT(ROW()-1,"000")) -> CMP004 | B5: 45989 | C5: MWANGI, MERCY WANJIRU | D5: 23694742 | E5: 254727468904 | F5: JACKSON NJOROGE | G5: NYERI | H5: System Underperformance | I5: system under performing | J5: Non Performing | K5: 44098 | L5: Open | O5: =IF(L5="Closed","",IF(B5="","",TODAY()-B5)) -> 138 | P5: {=IF(L5<>"Open","",IFS(TODAY()-B5<=30,"Low",TODAY()-B5<=60,"Moderate",TODAY()-B5>60,"High"))} -> High
A6: =IF(B6="","","CMP"&TEXT(ROW()-1,"000")) -> CMP005 | B6: 45989 | C6: MWANGI , PETER MUYAIRA | D6: 28499942 | E6: 254700514693 | F6: JACKSON NJOROGE | G6: NYERI | H6: System Underperformance | I6: system under performing | J6: Non Performing | K6: 31319 | L6: Open | O6: =IF(L6="Closed","",IF(B6="","",TODAY()-B6)) -> 138 | P6: {=IF(L6<>"Open","",IFS(TODAY()-B6<=30,"Low",TODAY()-B6<=60,"Moderate",TODAY()-B6>60,"High"))} -> High
A7: =IF(B7="","","CMP"&TEXT(ROW()-1,"000")) -> CMP006 | B7: 45868 | C7: RUTERE, IBRAHIM KIMATHI | D7: 24252200 | E7: 254721123649 | F7: JACKSON NJOROGE | G7: NYERI | H7: System Underperformance | I7: system under performing | J7: Non Performing | K7: 35104 | L7: Waiting for Customer | M7: Customer had said he lacked water for reinstallation | O7: =IF(L7="Closed","",IF(B7="","",TODAY()-B7)) -> 259 | P7: {=IF(L7<>"Open","",IFS(TODAY()-B7<=30,"Low",TODAY()-B7<=60,"Moderate",TODAY()-B7>60,"High"))}
A8: =IF(B8="","","CMP"&TEXT(ROW()-1,"000")) | C8: JAMES GATURA KIMANI | D8: 21131822 | E8: 254729812095 | F8: JACKSON NJOROGE | G8: MURANGA | H8: System Underperformance | I8: system under performing since installation | J8: Non Performing | K8: 35607 | O8: =IF(L8="Closed","",IF(B8="","",TODAY()-B8)) | P8: {=IF(L8<>"Open","",IFS(TODAY()-B8<=30,"Low",TODAY()-B8<=60,"Moderate",TODAY()-B8>60,"High"))}
A9: =IF(B9="","","CMP"&TEXT(ROW()-1,"000")) -> CMP008 | B9: 46092 | C9: KINUTHIA, ROSE WANJIKU | D9: 26459123 | E9: 254706156860 | F9: JOHN MUIRURI | G9: MURANGA | H9: System Underperformance | I9: Collapsed system | J9: Non Performing | K9: 14153 | O9: =IF(L9="Closed","",IF(B9="","",TODAY()-B9)) -> 35 | P9: {=IF(L9<>"Open","",IFS(TODAY()-B9<=30,"Low",TODAY()-B9<=60,"Moderate",TODAY()-B9>60,"High"))}
A10: =IF(B10="","","CMP"&TEXT(ROW()-1,"000")) | C10: MARTHA MUGURE | D10: 11467049 | E10: 254727705815 | G10: MURANGA | H10: System Underperformance | I10: system under performing | J10: Non Performing | K10: 14153 | L10: Closed | O10: =IF(L10="Closed","",IF(B10="","",TODAY()-B10)) | P10: {=IF(L10<>"Open","",IFS(TODAY()-B10<=30,"Low",TODAY()-B10<=60,"Moderate",TODAY()-B10>60,"High"))}
A11: =IF(B11="","","CMP"&TEXT(ROW()-1,"000")) | C11: DAVID NDWIGA | E11: 254720046879 | F11: ALEX KAIRU | G11: EMBU | H11: System Underperformance | I11: system under performing | J11: Cleared | K11: 0 | L11: Closed | O11: =IF(L11="Closed","",IF(B11="","",TODAY()-B11)) | P11: {=IF(L11<>"Open","",IFS(TODAY()-B11<=30,"Low",TODAY()-B11<=60,"Moderate",TODAY()-B11>60,"High"))}
A12: =IF(B12="","","CMP"&TEXT(ROW()-1,"000")) -> CMP011 | B12: 45974 | C12: NICASIO NJUE | D12: 25980575 | E12: 254710113135 | F12: ALEX KAIRU | G12: EMBU | H12: System Underperformance | I12: less cooking hours | J12: Cleared | K12: 0 | L12: Closed | O12: =IF(L12="Closed","",IF(B12="","",TODAY()-B12)) | P12: {=IF(L12<>"Open","",IFS(TODAY()-B12<=30,"Low",TODAY()-B12<=60,"Moderate",TODAY()-B12>60,"High"))}
A13: =IF(B13="","","CMP"&TEXT(ROW()-1,"000")) -> CMP012 | B13: 46043 | C13: SERAPHINA WANGUI | D13: 11380129 | E13: 254710113135 | F13: ALEX KAIRU | G13: EMBU | H13: Pipe Damage/Disconnection | I13: cracked pipes | J13: Cleared | K13: 0 | L13: Closed | O13: =IF(L13="Closed","",IF(B13="","",TODAY()-B13)) | P13: {=IF(L13<>"Open","",IFS(TODAY()-B13<=30,"Low",TODAY()-B13<=60,"Moderate",TODAY()-B13>60,"High"))}
A14: =IF(B14="","","CMP"&TEXT(ROW()-1,"000")) -> CMP013 | B14: 46044 | C14: JOSPHAT NDWIGA | D14: 26341089 | E14: 254724275041 | F14: ALEX KAIRU | G14: EMBU | H14: System Underperformance | I14: less cooking hours | J14: Cleared | K14: 0 | L14: Closed | O14: =IF(L14="Closed","",IF(B14="","",TODAY()-B14)) | P14: {=IF(L14<>"Open","",IFS(TODAY()-B14<=30,"Low",TODAY()-B14<=60,"Moderate",TODAY()-B14>60,"High"))}
A15: =IF(B15="","","CMP"&TEXT(ROW()-1,"000")) -> CMP014 | B15: 45971 | C15: ROSE RUGURU | D15: 11598558 | E15: 254721552446 | F15: ALEX KAIRU | G15: EMBU | H15: System Underperformance | I15: system under performing | J15: Cleared | K15: 0 | L15: Closed | O15: =IF(L15="Closed","",IF(B15="","",TODAY()-B15)) | P15: {=IF(L15<>"Open","",IFS(TODAY()-B15<=30,"Low",TODAY()-B15<=60,"Moderate",TODAY()-B15>60,"High"))}
A16: =IF(B16="","","CMP"&TEXT(ROW()-1,"000")) -> CMP015 | B16: 45971 | C16: MOSES MURIITHI | D16: 38237349 | E16: 254704118374 | F16: ALEX KAIRU | G16: EMBU | H16: Pipe Damage/Disconnection | I16: broken outlet | J16: Non Performing | K16: 18653 | L16: Closed | O16: =IF(L16="Closed","",IF(B16="","",TODAY()-B16)) | P16: {=IF(L16<>"Open","",IFS(TODAY()-B16<=30,"Low",TODAY()-B16<=60,"Moderate",TODAY()-B16>60,"High"))}
A17: =IF(B17="","","CMP"&TEXT(ROW()-1,"000")) -> CMP016 | B17: 45972 | C17: JOSEPH MUTIGI | D17: 220694429 | E17: 254722481657 | F17: ALEX KAIRU | G17: EMBU | H17: System Underperformance | I17: system under performing | J17: Non Performing | K17: 20736 | L17: Closed | O17: =IF(L17="Closed","",IF(B17="","",TODAY()-B17)) | P17: {=IF(L17<>"Open","",IFS(TODAY()-B17<=30,"Low",TODAY()-B17<=60,"Moderate",TODAY()-B17>60,"High"))}
A18: =IF(B18="","","CMP"&TEXT(ROW()-1,"000")) -> CMP017 | B18: 45976 | C18: MORRIS NJIRU MRITHAA | D18: 7010512 | E18: 254768068199 | F18: DICKSON MWANGI | G18: THARAKA NITHI | H18: Pipe Damage/Disconnection | I18: Gas leakage at kichen | J18: Non Performing | K18: 1902 | L18: Closed | O18: =IF(L18="Closed","",IF(B18="","",TODAY()-B18)) | P18: {=IF(L18<>"Open","",IFS(TODAY()-B18<=30,"Low",TODAY()-B18<=60,"Moderate",TODAY()-B18>60,"High"))}
A19: =IF(B19="","","CMP"&TEXT(ROW()-1,"000")) -> CMP018 | B19: 46093 | C19: DUNCAN KENNETH MICHENI | D19: 13356487 | E19: 254727628270 | F19: ERASTUS IRUNGU | G19: THARAKA NITHI | H19: Diconnected Oulet | I19: Disconnected Oulet leading to slurry leakage | J19: Non Performing | K19: 8653 | L19: Open | O19: =IF(L19="Closed","",IF(B19="","",TODAY()-B19)) -> 34 | P19: {=IF(L19<>"Open","",IFS(TODAY()-B19<=30,"Low",TODAY()-B19<=60,"Moderate",TODAY()-B19>60,"High"))} -> Moderate
A20: =IF(B20="","","CMP"&TEXT(ROW()-1,"000")) -> CMP019 | B20: 46013 | C20: MICHAEL NJUE GACHUGO | D20: 3738795 | E20: 254704782935 | F20: SIMON KANYI | G20: EMBU | H20: Pipe Damage/Disconnection | I20: Creacked Pipes | J20: Non Performing | K20: 45186 | L20: Closed | O20: =IF(L20="Closed","",IF(B20="","",TODAY()-B20)) | P20: {=IF(L20<>"Open","",IFS(TODAY()-B20<=30,"Low",TODAY()-B20<=60,"Moderate",TODAY()-B20>60,"High"))}
A21: =IF(B21="","","CMP"&TEXT(ROW()-1,"000")) -> CMP020 | B21: 46045 | C21: JOSEPH MUTIE NZIOKA | D21: 20050600 | E21: 254722878751 | F21: DICKSON MWANGI | G21: KIRINYAGA | H21: Pipe Damage/Disconnection | I21: Cracked pipe,Blocked inlet | J21: Non Performing | K21: 33647 | O21: =IF(L21="Closed","",IF(B21="","",TODAY()-B21)) -> 82 | P21: {=IF(L21<>"Open","",IFS(TODAY()-B21<=30,"Low",TODAY()-B21<=60,"Moderate",TODAY()-B21>60,"High"))}
A22: =IF(B22="","","CMP"&TEXT(ROW()-1,"000")) -> CMP021 | B22: 45927 | C22: ISAIAH KITHINJI SAMUEL | D22: 22013810 | E22: 254712715077 | F22: DICKSON MWANGI | G22: MERU | H22: System Underperformance | I22: system has less gas production despite being advised what to do. | J22: Non Performing | K22: 33633 | O22: =IF(L22="Closed","",IF(B22="","",TODAY()-B22)) -> 200 | P22: {=IF(L22<>"Open","",IFS(TODAY()-B22<=30,"Low",TODAY()-B22<=60,"Moderate",TODAY()-B22>60,"High"))}
A23: =IF(B23="","","CMP"&TEXT(ROW()-1,"000")) -> CMP022 | B23: 46052 | C23: JOSEPHAT BUNDI M'MARETE | D23: 2507130 | E23: 254721880142 | F23: DICKSON MWANGI | G23: MERU | H23: System Underperformance | I23: system under performing | J23: Non Performing | K23: 35753 | L23: Closed | O23: =IF(L23="Closed","",IF(B23="","",TODAY()-B23)) | P23: {=IF(L23<>"Open","",IFS(TODAY()-B23<=30,"Low",TODAY()-B23<=60,"Moderate",TODAY()-B23>60,"High"))}
A24: =IF(B24="","","CMP"&TEXT(ROW()-1,"000")) -> CMP023 | B24: 46074 | C24: FAITH KAARI DAVID | D24: 7461017 | E24: 254794483912 | F24: DICKSON MWANGI | G24: MERU | H24: System Damage(Tear/Burst) | I24: Tear on the system leading to leakage | J24: Non Performing | K24: 41080 | L24: Closed | O24: =IF(L24="Closed","",IF(B24="","",TODAY()-B24)) | P24: {=IF(L24<>"Open","",IFS(TODAY()-B24<=30,"Low",TODAY()-B24<=60,"Moderate",TODAY()-B24>60,"High"))}
A25: =IF(B25="","","CMP"&TEXT(ROW()-1,"000")) | C25: LEONARD NTURIBI | D25: 398828 | E25: 254720680592 | F25: DICKSON MWANGI | G25: MERU | H25: Gas Leakage | I25: reports system has not been working properly and suspects a leakage in the house | J25: Performing | K25: 0 | O25: =IF(L25="Closed","",IF(B25="","",TODAY()-B25)) | P25: {=IF(L25<>"Open","",IFS(TODAY()-B25<=30,"Low",TODAY()-B25<=60,"Moderate",TODAY()-B25>60,"High"))}
A26: =IF(B26="","","CMP"&TEXT(ROW()-1,"000")) -> CMP025 | B26: 45954 | C26: SALOME KINYA | D26: 9697802 | E26: 254712239395 | F26: DICKSON MWANGI | G26: MERU | J26: Non Performing | K26: 12295 | L26: Closed | O26: =IF(L26="Closed","",IF(B26="","",TODAY()-B26)) | P26: {=IF(L26<>"Open","",IFS(TODAY()-B26<=30,"Low",TODAY()-B26<=60,"Moderate",TODAY()-B26>60,"High"))}
A27: =IF(B27="","","CMP"&TEXT(ROW()-1,"000")) | C27: MERCY RIARA | D27: 27677504 | E27: 254703846037 | F27: DICKSON MWANGI | G27: MERU | J27: Performing | K27: 0 | O27: =IF(L27="Closed","",IF(B27="","",TODAY()-B27)) | P27: {=IF(L27<>"Open","",IFS(TODAY()-B27<=30,"Low",TODAY()-B27<=60,"Moderate",TODAY()-B27>60,"High"))}
A28: =IF(B28="","","CMP"&TEXT(ROW()-1,"000")) -> CMP027 | B28: 45980 | C28: JULIA KIORO | E28: 254719820192 | F28: DICKSON MWANGI | G28: MERU | H28: Gas Leakage | I28: Disconnection at the point piping connects to the unit leading yo gas leakage | J28: Performing | K28: 0 | L28: Closed | O28: =IF(L28="Closed","",IF(B28="","",TODAY()-B28)) | P28: {=IF(L28<>"Open","",IFS(TODAY()-B28<=30,"Low",TODAY()-B28<=60,"Moderate",TODAY()-B28>60,"High"))}
A29: =IF(B29="","","CMP"&TEXT(ROW()-1,"000")) -> CMP028 | B29: 45918 | C29: GRACE KAIMURI KATHUNI | D29: 21782701 | E29: 254703959341 | F29: DICKSON MWANGI | G29: MERU | H29: System Underperformance | I29: System is underperforming despite following instrustions | J29: Performing | K29: 0 | L29: Closed | O29: =IF(L29="Closed","",IF(B29="","",TODAY()-B29)) | P29: {=IF(L29<>"Open","",IFS(TODAY()-B29<=30,"Low",TODAY()-B29<=60,"Moderate",TODAY()-B29>60,"High"))}
A30: =IF(B30="","","CMP"&TEXT(ROW()-1,"000")) -> CMP029 | B30: 45995 | C30: ALBERT, JULIUS KIRIMI | D30: 7010512 | E30: 254722759231 | F30: ERASTUS IRUNGU | G30: THARAKA NITHI | H30: System Underperformance | I30: Complains system cant sustain cooking tea despite following the procedures given to maintain the system. | J30: Non Performing | K30: 8652 | L30: Closed | O30: =IF(L30="Closed","",IF(B30="","",TODAY()-B30)) | P30: {=IF(L30<>"Open","",IFS(TODAY()-B30<=30,"Low",TODAY()-B30<=60,"Moderate",TODAY()-B30>60,"High"))}
A31: =IF(B31="","","CMP"&TEXT(ROW()-1,"000")) | O31: =IF(L31="Closed","",IF(B31="","",TODAY()-B31)) | P31: {=IF(L31<>"Open","",IFS(TODAY()-B31<=30,"Low",TODAY()-B31<=60,"Moderate",TODAY()-B31>60,"High"))}
A32: =IF(B32="","","CMP"&TEXT(ROW()-1,"000")) | O32: =IF(L32="Closed","",IF(B32="","",TODAY()-B32))
A33: =IF(B33="","","CMP"&TEXT(ROW()-1,"000")) | O33: =IF(L33="Closed","",IF(B33="","",TODAY()-B33))
A34: =IF(B34="","","CMP"&TEXT(ROW()-1,"000")) | O34: =IF(L34="Closed","",IF(B34="","",TODAY()-B34))
A35: =IF(B35="","","CMP"&TEXT(ROW()-1,"000")) | O35: =IF(L35="Closed","",IF(B35="","",TODAY()-B35))
A36: =IF(B36="","","CMP"&TEXT(ROW()-1,"000")) | O36: =IF(L36="Closed","",IF(B36="","",TODAY()-B36))
A37: =IF(B37="","","CMP"&TEXT(ROW()-1,"000")) | O37: =IF(L37="Closed","",IF(B37="","",TODAY()-B37))
A38: =IF(B38="","","CMP"&TEXT(ROW()-1,"000")) | O38: =IF(L38="Closed","",IF(B38="","",TODAY()-B38))
A39: =IF(B39="","","CMP"&TEXT(ROW()-1,"000")) | O39: =IF(L39="Closed","",IF(B39="","",TODAY()-B39))
A40: =IF(B40="","","CMP"&TEXT(ROW()-1,"000")) | O40: =IF(L40="Closed","",IF(B40="","",TODAY()-B40))
...
